#VRML_SIM R2023b utf8

EXTERNPROTO "https://raw.githubusercontent.com/cyberbotics/webots/R2023b/projects/appearances/protos/OsbWood.proto"
EXTERNPROTO "https://raw.githubusercontent.com/cyberbotics/webots/R2023b/projects/objects/floors/protos/RectangleArena.proto"
EXTERNPROTO "https://raw.githubusercontent.com/cyberbotics/webots/R2023b/projects/objects/backgrounds/protos/TexturedBackground.proto"
EXTERNPROTO "https://raw.githubusercontent.com/cyberbotics/webots/R2023b/projects/objects/backgrounds/protos/TexturedBackgroundLight.proto"

WorldInfo {
  info [
    "In this example, the robot turns on a slope."
    "Its accelerometer sensor is used to switch on the bottommost LED."
  ]
  title "Accelerometer"
  basicTimeStep 8
  contactProperties [
    ContactProperties {
      material2 "body"
      coulombFriction [
        0
      ]
      softCFM 0.1
    }
  ]
}
Viewpoint {
  orientation -0.054199861290779465 -0.002183744456951236 0.9985277193429369 3.7898969330473973
  position 0.6541222541001334 0.6817670371024325 0.33717442018929844
}
TexturedBackground {
}
TexturedBackgroundLight {
}
RectangleArena {
}
PointLight {
  attenuation 0 0 1
  intensity 0.6
  location 0.6 0 0
}
DEF SLOPE Solid {
  translation 0 0 0.15
  rotation 1 0 0 -1.970795
  children [
    Shape {
      appearance OsbWood {
        textureTransform TextureTransform {
          scale 0.5 2
        }
      }
      geometry DEF BOX0 Box {
        size 0.2 0.02 0.8
      }
    }
  ]
  name "green box"
  boundingObject USE BOX0
}
Robot {
  translation -0.010004879292355879 0.032633789269284924 0.14708934406814378
  rotation -0.506541125901038 0.2528421829935593 0.8243099649221524 0.8061187046275221
  children [
    Accelerometer {
    }
    DEF LeftWheel HingeJoint {
      jointParameters HingeJointParameters {
        position 0.252
        axis 0 1 0
        anchor 0 0 0.025
      }
      device [
        PositionSensor {
          name "left wheel sensor"
        }
        RotationalMotor {
          name "left wheel motor"
          consumptionFactor 70
        }
      ]
      endPoint Solid {
        translation 0 0.045 0.025
        rotation 0.5221974279487018 -0.5221974279487018 -0.6742549165467913 1.956
        children [
          Transform {
            rotation 0.5773502691896258 0.5773502691896258 -0.5773502691896258 -2.094
            children [
              Shape {
                appearance PBRAppearance {
                  baseColor 1 0 0
                  roughness 1
                  metalness 0
                }
                geometry Cylinder {
                  height 0.01
                  radius 0.025
                }
              }
            ]
          }
        ]
      }
    }
    DEF RightWheel HingeJoint {
      jointParameters HingeJointParameters {
        position 0.252
        axis 0 1 0
        anchor 0 0 0.025
      }
      device [
        PositionSensor {
          name "right wheel sensor"
        }
        RotationalMotor {
          name "right wheel motor"
          consumptionFactor 70
        }
      ]
      endPoint Solid {
        translation 0 -0.045 0.025
        rotation 0.5221974279487018 -0.5221974279487018 -0.6742549165467913 1.956
        children [
          Transform {
            rotation 0.5773502691896258 0.5773502691896258 -0.5773502691896258 -2.094
            children [
              Shape {
                appearance PBRAppearance {
                  baseColor 1 0 0
                  roughness 1
                  metalness 0
                }
                geometry Cylinder {
                  height 0.01
                  radius 0.025
                }
              }
            ]
          }
        ]
        name "solid(1)"
      }
    }
    Pose {
      translation 0 0 0.0415
      children [
        Shape {
          appearance PBRAppearance {
            baseColor 0.0820075 0.364731 0.8
            roughness 1
            metalness 0
          }
          geometry DEF BODY Cylinder {
            height 0.08
            radius 0.045
          }
        }
      ]
    }
  ]
  name "MyBot"
  contactMaterial "body"
  boundingObject Pose {
    translation 0 0 0.0415
    rotation 0 0 1 -1.570796
    children [
      USE BODY
    ]
  }
  physics Physics {
    density -1
    mass 0.5
  }
  controller "accelerometer"
  linearVelocity 0.0007910325193746955 0.0002346463782198548 -8.94014605089382e-05
  angularVelocity 0.009290543242779838 -0.1186752017027373 -0.25136684982452284
}
